Workbook

Sheet 2025_Draft_team
B2: Round | C2: Pick | D2: Team | E2: PlayerMatch
B3: 1 | C3: 1 | D3: Gatordontplay | E3: {=INDEX('2024_Roster_Offseason'!$I$2:$I$301,MATCH(1,('2025_Draft_team'!$D3='2024_Roster_Offseason'!$A$2:$A$301)*('2025_Draft_team'!$B3='2024_Roster_Offseason'!$P$2:$P$301)*('2024_Roster_Offseason'!$Q$2:$Q$301="Y"),0))} -> #N/A
B4: 1 | C4: 2 | D4: Box of Rocks | E4: {=INDEX('2024_Roster_Offseason'!$I$2:$I$301,MATCH(1,('2025_Draft_team'!$D4='2024_Roster_Offseason'!$A$2:$A$301)*('2025_Draft_team'!$B4='2024_Roster_Offseason'!$P$2:$P$301)*('2024_Roster_Offseason'!$Q$2:$Q$301="Y"),0))} -> #N/A
B5: 1 | C5: 3 | D5: Woody and the Jets! | E5: {=INDEX('2024_Roster_Offseason'!$I$2:$I$301,MATCH(1,('2025_Draft_team'!$D5='2024_Roster_Offseason'!$A$2:$A$301)*('2025_Draft_team'!$B5='2024_Roster_Offseason'!$P$2:$P$301)*('2024_Roster_Offseason'!$Q$2:$Q$301="Y"),0))} -> #N/A
B6: 1 | C6: 4 | D6: Go Go Garrett | E6: {=INDEX('2024_Roster_Offseason'!$I$2:$I$301,MATCH(1,('2025_Draft_team'!$D6='2024_Roster_Offseason'!$A$2:$A$301)*('2025_Draft_team'!$B6='2024_Roster_Offseason'!$P$2:$P$301)*('2024_Roster_Offseason'!$Q$2:$Q$301="Y"),0))} -> #N/A
B7: 1 | C7: 5 | D7: Discount Belichick | E7: {=INDEX('2024_Roster_Offseason'!$I$2:$I$301,MATCH(1,('2025_Draft_team'!$D7='2024_Roster_Offseason'!$A$2:$A$301)*('2025_Draft_team'!$B7='2024_Roster_Offseason'!$P$2:$P$301)*('2024_Roster_Offseason'!$Q$2:$Q$301="Y"),0))} -> #N/A
B8: 1 | C8: 6 | D8: Team 4 | E8: {=INDEX('2024_Roster_Offseason'!$I$2:$I$301,MATCH(1,('2025_Draft_team'!$D8='2024_Roster_Offseason'!$A$2:$A$301)*('2025_Draft_team'!$B8='2024_Roster_Offseason'!$P$2:$P$301)*('2024_Roster_Offseason'!$Q$2:$Q$301="Y"),0))} -> #N/A
B9: 1 | C9: 7 | D9: The Bushwhackers | E9: {=INDEX('2024_Roster_Offseason'!$I$2:$I$301,MATCH(1,('2025_Draft_team'!$D9='2024_Roster_Offseason'!$A$2:$A$301)*('2025_Draft_team'!$B9='2024_Roster_Offseason'!$P$2:$P$301)*('2024_Roster_Offseason'!$Q$2:$Q$301="Y"),0))} -> #N/A
B10: 1 | C10: 8 | D10: Sweet Chin Music | E10: {=INDEX('2024_Roster_Offseason'!$I$2:$I$301,MATCH(1,('2025_Draft_team'!$D10='2024_Roster_Offseason'!$A$2:$A$301)*('2025_Draft_team'!$B10='2024_Roster_Offseason'!$P$2:$P$301)*('2024_Roster_Offseason'!$Q$2:$Q$301="Y"),0))} -> #N/A
B11: 1 | C11: 9 | D11: Fields of Dreams | E11: {=INDEX('2024_Roster_Offseason'!$I$2:$I$301,MATCH(1,('2025_Draft_team'!$D11='2024_Roster_Offseason'!$A$2:$A$301)*('2025_Draft_team'!$B11='2024_Roster_Offseason'!$P$2:$P$301)*('2024_Roster_Offseason'!$Q$2:$Q$301="Y"),0))} -> JaydenDaniels
B12: 1 | C12: 10 | D12: Let Bijans be Bijans | E12: {=INDEX('2024_Roster_Offseason'!$I$2:$I$301,MATCH(1,('2025_Draft_team'!$D12='2024_Roster_Offseason'!$A$2:$A$301)*('2025_Draft_team'!$B12='2024_Roster_Offseason'!$P$2:$P$301)*('2024_Roster_Offseason'!$Q$2:$Q$301="Y"),0))} -> #N/A
B13: 2 | C13: 1 | D13: Gatordontplay | E13: {=INDEX('2024_Roster_Offseason'!$I$2:$I$301,MATCH(1,('2025_Draft_team'!$D13='2024_Roster_Offseason'!$A$2:$A$301)*('2025_Draft_team'!$B13='2024_Roster_Offseason'!$P$2:$P$301)*('2024_Roster_Offseason'!$Q$2:$Q$301="Y"),0))} -> #N/A
B14: 2 | C14: 2 | D14: Box of Rocks | E14: {=INDEX('2024_Roster_Offseason'!$I$2:$I$301,MATCH(1,('2025_Draft_team'!$D14='2024_Roster_Offseason'!$A$2:$A$301)*('2025_Draft_team'!$B14='2024_Roster_Offseason'!$P$2:$P$301)*('2024_Roster_Offseason'!$Q$2:$Q$301="Y"),0))} -> #N/A
... B272: 27 | C272: 10 | D272: Let Bijans be Bijans | E272: {=INDEX('2024_Roster_Offseason'!$I$2:$I$301,MATCH(1,('2025_Draft_team'!$D272='2024_Roster_Offseason'!$A$2:$A$301)*('2025_Draft_team'!$B272='2024_Roster_Offseason'!$P$2:$P$301)*('2024_Roster_Offseason'!$Q$2:$Q$301="Y"),0))} -> #N/A

Sheet 2024_Roster_Offseason
A1: Team | B1: Pos | C1: First | D1: Last | E1: Position | F1: Blank | G1: Team2 | H1: PosRnk | I1: PlayerMatch | J1: Rost | K1: Start | L1: Prd. 22 | M1: Avg | N1: Proj | O1: 2024Transactions | P1: 2025Draft | Q1: Keeper
A2: Box of Rocks | B2: QB | C2: Derek | D2: Carr | E2: QB | F2: | | G2: NO | I2: ='2024_Roster_Offseason'!$C2&'2024_Roster_Offseason'!$D2 -> DerekCarr | J2: 0.36 | K2: 0.05 | L2: 0 | M2: 33.6 | N2: 0 | O2: {=INDEX('2024_Transactions'!$J$2:$J$339,MATCH(1,('2024_Transactions'!$C$2:$C$339='2024_Roster_Offseason'!$I2)*('2024_Roster_Offseason'!$A2='2024_Transactions'!$B$2:$B$339),0))} -> #N/A | P2: {=INDEX('2024_Draft_team'!$J$2:$J$271,MATCH(1,('2024_Roster_Offseason'!$I2='2024_Draft_team'!$Q$2:$Q$271)*('2024_Roster_Offseason'!$A2='2024_Draft_team'!$B$2:$B$271),0))} -> 6 | Q2: N
A3: Box of Rocks | B3: QB | C3: Brock | D3: Purdy | E3: QB | F3: | | G3: SF | I3: ='2024_Roster_Offseason'!$C3&'2024_Roster_Offseason'!$D3 -> BrockPurdy | J3: 0.94 | K3: 0.48 | L3: 0 | M3: 38.07 | N3: 0 | O3: {=INDEX('2024_Transactions'!$J$2:$J$339,MATCH(1,('2024_Transactions'!$C$2:$C$339='2024_Roster_Offseason'!$I3)*('2024_Roster_Offseason'!$A3='2024_Transactions'!$B$2:$B$339),0))} -> #N/A | P3: {=INDEX('2024_Draft_team'!$J$2:$J$271,MATCH(1,('2024_Roster_Offseason'!$I3='2024_Draft_team'!$Q$2:$Q$271)*('2024_Roster_Offseason'!$A3='2024_Draft_team'!$B$2:$B$271),0))} -> 8 | Q3: Y
A4: Box of Rocks | B4: RB | C4: Nick | D4: Chubb | E4: RB | F4: | | G4: CLE | I4: ='2024_Roster_Offseason'!$C4&'2024_Roster_Offseason'!$D4 -> NickChubb | J4: 0.74 | K4: 0.19 | L4: 0 | M4: 13.38 | N4: 0 | O4: {=INDEX('2024_Transactions'!$J$2:$J$339,MATCH(1,('2024_Transactions'!$C$2:$C$339='2024_Roster_Offseason'!$I4)*('2024_Roster_Offseason'!$A4='2024_Transactions'!$B$2:$B$339),0))} -> #N/A | P4: {=INDEX('2024_Draft_team'!$J$2:$J$271,MATCH(1,('2024_Roster_Offseason'!$I4='2024_Draft_team'!$Q$2:$Q$271)*('2024_Roster_Offseason'!$A4='2024_Draft_team'!$B$2:$B$271),0))} -> 16 | Q4: N
A5: Box of Rocks | B5: RB | C5: Josh | D5: Jacobs | E5: RB | F5: | | G5: GB | I5: ='2024_Roster_Offseason'!$C5&'2024_Roster_Offseason'!$D5 -> JoshJacobs | J5: 1 | K5: 0.98 | L5: 0 | M5: 30.06 | N5: 0 | O5: {=INDEX('2024_Transactions'!$J$2:$J$339,MATCH(1,('2024_Transactions'!$C$2:$C$339='2024_Roster_Offseason'!$I5)*('2024_Roster_Offseason'!$A5='2024_Transactions'!$B$2:$B$339),0))} -> #N/A | P5: {=INDEX('2024_Draft_team'!$J$2:$J$271,MATCH(1,('2024_Roster_Offseason'!$I5='2024_Draft_team'!$Q$2:$Q$271)*('2024_Roster_Offseason'!$A5='2024_Draft_team'!$B$2:$B$271),0))} -> 1 | Q5: N
A6: Box of Rocks | B6: WR-TE | C6: Davante | D6: Adams | E6: WR-TE | F6: | | G6: NYJ | I6: ='2024_Roster_Offseason'!$C6&'2024_Roster_Offseason'!$D6 -> DavanteAdams | J6: 1 | K6: 0.88 | L6: 0 | M6: 27 | N6: 0 | O6: {=INDEX('2024_Transactions'!$J$2:$J$339,MATCH(1,('2024_Transactions'!$C$2:$C$339='2024_Roster_Offseason'!$I6)*('2024_Roster_Offseason'!$A6='2024_Transactions'!$B$2:$B$339),0))} -> #N/A | P6: {=INDEX('2024_Draft_team'!$J$2:$J$271,MATCH(1,('2024_Roster_Offseason'!$I6='2024_Draft_team'!$Q$2:$Q$271)*('2024_Roster_Offseason'!$A6='2024_Draft_team'!$B$2:$B$271),0))} -> 3 | Q6: N
A7: Box of Rocks | B7: WR-TE | C7: Jauan | D7: Jennings | E7: WR-TE | F7: | | G7: SF | I7: ='2024_Roster_Offseason'!$C7&'2024_Roster_Offseason'!$D7 -> JauanJennings | J7: 0.94 | K7: 0.61 | L7: 0 | M7: 22.13 | N7: 0 | O7: {=INDEX('2024_Transactions'!$J$2:$J$339,MATCH(1,('2024_Transactions'!$C$2:$C$339='2024_Roster_Offseason'!$I7)*('2024_Roster_Offseason'!$A7='2024_Transactions'!$B$2:$B$339),0))} -> Signed | P7: {=IFERROR(INDEX('2024_Draft_team'!$J$2:$J$271,MATCH(1,('2024_Roster_Offseason'!$I7='2024_Draft_team'!$Q$2:$Q$271)*('2024_Roster_Offseason'!$A7='2024_Draft_team'!$B$2:$B$271),0)),15)} -> 15 | Q7: Y
A8: Box of Rocks | B8: WR-TE | C8: Quentin | D8: Johnston | E8: WR-TE | F8: | | G8: LAC | I8: ='2024_Roster_Offseason'!$C8&'2024_Roster_Offseason'!$D8 -> QuentinJohnston | J8: 0.8 | K8: 0.28 | L8: 0 | M8: 18.93 | N8: 0 | O8: {=INDEX('2024_Transactions'!$J$2:$J$339,MATCH(1,('2024_Transactions'!$C$2:$C$339='2024_Roster_Offseason'!$I8)*('2024_Roster_Offseason'!$A8='2024_Transactions'!$B$2:$B$339),0))} -> Signed | P8: {=IFERROR(INDEX('2024_Draft_team'!$J$2:$J$271,MATCH(1,('2024_Roster_Offseason'!$I8='2024_Draft_team'!$Q$2:$Q$271)*('2024_Roster_Offseason'!$A8='2024_Draft_team'!$B$2:$B$271),0)),15)} -> 15 | Q8: N
A9: Box of Rocks | B9: K | C9: Jason | D9: Sanders | E9: K | F9: | | G9: MIA | I9: ='2024_Roster_Offseason'!$C9&'2024_Roster_Offseason'!$D9 -> JasonSanders | J9: 0.87 | K9: 0.73 | L9: 0 | M9: 20.18 | N9: 0 | O9: {=INDEX('2024_Transactions'!$J$2:$J$339,MATCH(1,('2024_Transactions'!$C$2:$C$339='2024_Roster_Offseason'!$I9)*('2024_Roster_Offseason'!$A9='2024_Transactions'!$B$2:$B$339),0))} -> Signed | P9: {=IFERROR(INDEX('2024_Draft_team'!$J$2:$J$271,MATCH(1,('2024_Roster_Offseason'!$I9='2024_Draft_team'!$Q$2:$Q$271)*('2024_Roster_Offseason'!$A9='2024_Draft_team'!$B$2:$B$271),0)),15)} -> 15 | Q9: N
A10: Box of Rocks | B10: DL-LB-DB | C10: Jessie | D10: Bates | E10: III | F10: DL-LB-DB | G10: | | H10: ATL | I10: ='2024_Roster_Offseason'!$C10&'2024_Roster_Offseason'!$D10&'2024_Roster_Offseason'!$E10 -> JessieBatesIII | J10: 0.64 | K10: 0.52 | L10: 0 | M10: 19.76 | N10: 0 | O10: {=INDEX('2024_Transactions'!$J$2:$J$339,MATCH(1,('2024_Transactions'!$C$2:$C$339='2024_Roster_Offseason'!$I10)*('2024_Roster_Offseason'!$A10='2024_Transactions'!$B$2:$B$339),0))} -> #N/A | P10: {=INDEX('2024_Draft_team'!$J$2:$J$271,MATCH(1,('2024_Roster_Offseason'!$I10='2024_Draft_team'!$Q$2:$Q$271)*('2024_Roster_Offseason'!$A10='2024_Draft_team'!$B$2:$B$271),0))} -> 11 | Q10: Y
A11: Box of Rocks | B11: DL-LB-DB | C11: Kevin | D11: Byard | E11: DL-LB-DB | F11: | | G11: CHI | I11: ='2024_Roster_Offseason'!$C11&'2024_Roster_Offseason'!$D11 -> KevinByard | J11: 0.54 | K11: 0.45 | L11: 0 | M11: 20.82 | N11: 0 | O11: {=INDEX('2024_Transactions'!$J$2:$J$339,MATCH(1,('2024_Transactions'!$C$2:$C$339='2024_Roster_Offseason'!$I11)*('2024_Roster_Offseason'!$A11='2024_Transactions'!$B$2:$B$339),0))} -> Signed | P11: {=IFERROR(INDEX('2024_Draft_team'!$J$2:$J$271,MATCH(1,('2024_Roster_Offseason'!$I11='2024_Draft_team'!$Q$2:$Q$271)*('2024_Roster_Offseason'!$A11='2024_Draft_team'!$B$2:$B$271),0)),15)} -> 15 | Q11: N
A12: Box of Rocks | B12: DL-LB-DB | C12: Grant | D12: Delpit | E12: DL-LB-DB | F12: | | G12: CLE | I12: ='2024_Roster_Offseason'!$C12&'2024_Roster_Offseason'!$D12 -> GrantDelpit | J12: 0.55 | K12: 0.47 | L12: 0 | M12: 17.19 | N12: 0 | O12: {=INDEX('2024_Transactions'!$J$2:$J$339,MATCH(1,('2024_Transactions'!$C$2:$C$339='2024_Roster_Offseason'!$I12)*('2024_Roster_Offseason'!$A12='2024_Transactions'!$B$2:$B$339),0))} -> #N/A | P12: {=INDEX('2024_Draft_team'!$J$2:$J$271,MATCH(1,('2024_Roster_Offseason'!$I12='2024_Draft_team'!$Q$2:$Q$271)*('2024_Roster_Offseason'!$A12='2024_Draft_team'!$B$2:$B$271),0))} -> 18 | Q12: N
A13: Box of Rocks | B13: DL-LB-DB | C13: Amani | D13: Hooker | E13: DL-LB-DB | F13: | | G13: TEN | I13: ='2024_Roster_Offseason'!$C13&'2024_Roster_Offseason'!$D13 -> AmaniHooker | J13: 0.66 | K13: 0.47 | L13: 0 | M13: 19.14 | N13: 0 | O13: {=INDEX('2024_Transactions'!$J$2:$J$339,MATCH(1,('2024_Transactions'!$C$2:$C$339='2024_Roster_Offseason'!$I13)*('2024_Roster_Offseason'!$A13='2024_Transactions'!$B$2:$B$339),0))} -> #N/A | P13: {=INDEX('2024_Draft_team'!$J$2:$J$271,MATCH(1,('2024_Roster_Offseason'!$I13='2024_Draft_team'!$Q$2:$Q$271)*('2024_Roster_Offseason'!$A13='2024_Draft_team'!$B$2:$B$271),0))} -> 9 | Q13: N
A14: Box of Rocks | B14: DL-LB-DB | C14: Xavier | D14: McKinney | E14: DL-LB-DB | F14: | | G14: GB | I14: ='2024_Roster_Offseason'!$C14&'2024_Roster_Offseason'!$D14 -> XavierMcKinney | J14: 0.73 | K14: 0.64 | L14: 0 | M14: 22.06 | N14: 0 | O14: {=INDEX('2024_Transactions'!$J$2:$J$339,MATCH(1,('2024_Transactions'!$C$2:$C$339='2024_Roster_Offseason'!$I14)*('2024_Roster_Offseason'!$A14='2024_Transactions'!$B$2:$B$339),0))} -> #N/A | P14: {=INDEX('2024_Draft_team'!$J$2:$J$271,MATCH(1,('2024_Roster_Offseason'!$I14='2024_Draft_team'!$Q$2:$Q$271)*('2024_Roster_Offseason'!$A14='2024_Draft_team'!$B$2:$B$271),0))} -> 10 | Q14: N
A15: Box of Rocks | B15: DL-LB-DB | C15: Trevon | D15: Moehrig | E15: DL-LB-DB | F15: | | G15: LV | I15: ='2024_Roster_Offseason'!$C15&'2024_Roster_Offseason'!$D15 -> TrevonMoehrig | J15: 0.38 | K15: 0.3 | L15: 0 | M15: 18 | N15: 0 | O15: {=INDEX('2024_Transactions'!$J$2:$J$339,MATCH(1,('2024_Transactions'!$C$2:$C$339='2024_Roster_Offseason'!$I15)*('2024_Roster_Offseason'!$A15='2024_Transactions'!$B$2:$B$339),0))} -> Signed | P15: {=IFERROR(INDEX('2024_Draft_team'!$J$2:$J$271,MATCH(1,('2024_Roster_Offseason'!$I15='2024_Draft_team'!$Q$2:$Q$271)*('2024_Roster_Offseason'!$A15='2024_Draft_team'!$B$2:$B$271),0)),15)} -> 15 | Q15: N
A16: Box of Rocks | B16: DL-LB-DB | C16: Byron | D16: Murphy | E16: DL-LB-DB | F16: | | G16: MIN | I16: ='2024_Roster_Offseason'!$C16&'2024_Roster_Offseason'!$D16 -> ByronMurphy | J16: 0.28 | K16: 0.21 | L16: 0 | M16: 20.29 | N16: 0 | O16: {=INDEX('2024_Transactions'!$J$2:$J$339,MATCH(1,('2024_Transactions'!$C$2:$C$339='2024_Roster_Offseason'!$I16)*('2024_Roster_Offseason'!$A16='2024_Transactions'!$B$2:$B$339),0))} -> Signed | P16: {=IFERROR(INDEX('2024_Draft_team'!$J$2:$J$271,MATCH(1,('2024_Roster_Offseason'!$I16='2024_Draft_team'!$Q$2:$Q$271)*('2024_Roster_Offseason'!$A16='2024_Draft_team'!$B$2:$B$271),0)),15)} -> 15 | Q16: N
A17: Box of Rocks | B17: QB | C17: Tommy | D17: DeVito | E17: QB | F17: | | G17: NYG | I17: ='2024_Roster_Offseason'!$C17&'2024_Roster_Offseason'!$D17 -> TommyDeVito | J17: 0.06 | K17: 0.01 | L17: 0 | M17: 11.67 | N17: 0 | O17: {=INDEX('2024_Transactions'!$J$2:$J$339,MATCH(1,('2024_Transactions'!$C$2:$C$339='2024_Roster_Offseason'!$I17)*('2024_Roster_Offseason'!$A17='2024_Transactions'!$B$2:$B$339),0))} -> Signed | P17: {=IFERROR(INDEX('2024_Draft_team'!$J$2:$J$271,MATCH(1,('2024_Roster_Offseason'!$I17='2024_Draft_team'!$Q$2:$Q$271)*('2024_Roster_Offseason'!$A17='2024_Draft_team'!$B$2:$B$271),0)),15)} -> 15 | Q17: N
A18: Box of Rocks | B18: QB | C18: Jameis | D18: Winston | E18: QB | F18: | | G18: CLE | I18: ='2024_Roster_Offseason'!$C18&'2024_Roster_Offseason'!$D18 -> JameisWinston | J18: 0.34 | K18: 0.07 | L18: 0 | M18: 24 | N18: 0 | O18: {=INDEX('2024_Transactions'!$J$2:$J$339,MATCH(1,('2024_Transactions'!$C$2:$C$339='2024_Roster_Offseason'!$I18)*('2024_Roster_Offseason'!$A18='2024_Transactions'!$B$2:$B$339),0))} -> Signed | P18: {=IFERROR(INDEX('2024_Draft_team'!$J$2:$J$271,MATCH(1,('2024_Roster_Offseason'!$I18='2024_Draft_team'!$Q$2:$Q$271)*('2024_Roster_Offseason'!$A18='2024_Draft_team'!$B$2:$B$271),0)),15)} -> 15 | Q18: N
A19: Box of Rocks | B19: RB | C19: Rico | D19: Dowdle | E19: RB | F19: | | G19: DAL | I19: ='2024_Roster_Offseason'!$C19&'2024_Roster_Offseason'!$D19 -> RicoDowdle | J19: 0.97 | K19: 0.75 | L19: 0 | M19: 19.5 | N19: 0 | O19: {=INDEX('2024_Transactions'!$J$2:$J$339,MATCH(1,('2024_Transactions'!$C$2:$C$339='2024_Roster_Offseason'!$I19)*('2024_Roster_Offseason'!$A19='2024_Transactions'!$B$2:$B$339),0))} -> #N/A | P19: {=INDEX('2024_Draft_team'!$J$2:$J$271,MATCH(1,('2024_Roster_Offseason'!$I19='2024_Draft_team'!$Q$2:$Q$271)*('2024_Roster_Offseason'!$A19='2024_Draft_team'!$B$2:$B$271),0))} -> 19 | Q19: N
A20: Box of Rocks | B20: RB | C20: Kareem | D20: Hunt | E20: RB | F20: | | G20: KC | I20: ='2024_Roster_Offseason'!$C20&'2024_Roster_Offseason'!$D20 -> KareemHunt | J20: 0.8 | K20: 0.17 | L20: 1 | M20: 21.77 | N20: 0 | O20: {=INDEX('2024_Transactions'!$J$2:$J$339,MATCH(1,('2024_Transactions'!$C$2:$C$339='2024_Roster_Offseason'!$I20)*('2024_Roster_Offseason'!$A20='2024_Transactions'!$B$2:$B$339),0))} -> Signed | P20: {=IFERROR(INDEX('2024_Draft_team'!$J$2:$J$271,MATCH(1,('2024_Roster_Offseason'!$I20='2024_Draft_team'!$Q$2:$Q$271)*('2024_Roster_Offseason'!$A20='2024_Draft_team'!$B$2:$B$271),0)),15)} -> 15 | Q20: N
A21: Box of Rocks | B21: WR-TE | C21: Amari | D21: Cooper | E21: WR-TE | F21: | | G21: BUF | I21: ='2024_Roster_Offseason'!$C21&'2024_Roster_Offseason'!$D21 -> AmariCooper | J21: 0.91 | K21: 0.31 | L21: 0 | M21: 16.07 | N21: 0 | O21: {=INDEX('2024_Transactions'!$J$2:$J$339,MATCH(1,('2024_Transactions'!$C$2:$C$339='2024_Roster_Offseason'!$I21)*('2024_Roster_Offseason'!$A21='2024_Transactions'!$B$2:$B$339),0))} -> #N/A | P21: {=INDEX('2024_Draft_team'!$J$2:$J$271,MATCH(1,('2024_Roster_Offseason'!$I21='2024_Draft_team'!$Q$2:$Q$271)*('2024_Roster_Offseason'!$A21='2024_Draft_team'!$B$2:$B$271),0))} -> 7 | Q21: N
A22: Box of Rocks | B22: WR-TE | C22: Allen | D22: Lazard | E22: WR-TE | F22: | | G22: NYJ | I22: ='2024_Roster_Offseason'!$C22&'2024_Roster_Offseason'!$D22 -> AllenLazard | J22: 0.22 | K22: 0.03 | L22: 0 | M22: 17.33 | N22: 0 | O22: {=INDEX('2024_Transactions'!$J$2:$J$339,MATCH(1,('2024_Transactions'!$C$2:$C$339='2024_Roster_Offseason'!$I22)*('2024_Roster_Offseason'!$A22='2024_Transactions'!$B$2:$B$339),0))} -> Signed | P22: {=IFERROR(INDEX('2024_Draft_team'!$J$2:$J$271,MATCH(1,('2024_Roster_Offseason'!$I22='2024_Draft_team'!$Q$2:$Q$271)*('2024_Roster_Offseason'!$A22='2024_Draft_team'!$B$2:$B$271),0)),15)} -> 15 | Q22: N
A23: Box of Rocks | B23: WR-TE | C23: Terry | D23: McLaurin | E23: WR-TE | F23: | | G23: WAS | I23: ='2024_Roster_Offseason'!$C23&'2024_Roster_Offseason'!$D23 -> TerryMcLaurin | J23: 0.99 | K23: 0.84 | L23: 0 | M23: 30.53 | N23: 0 | O23: {=INDEX('2024_Transactions'!$J$2:$J$339,MATCH(1,('2024_Transactions'!$C$2:$C$339='2024_Roster_Offseason'!$I23)*('2024_Roster_Offseason'!$A23='2024_Transactions'!$B$2:$B$339),0))} -> #N/A | P23: {=INDEX('2024_Draft_team'!$J$2:$J$271,MATCH(1,('2024_Roster_Offseason'!$I23='2024_Draft_team'!$Q$2:$Q$271)*('2024_Roster_Offseason'!$A23='2024_Draft_team'!$B$2:$B$271),0))} -> 13 | Q23: Y
A24: Box of Rocks | B24: DL-LB-DB | C24: Chamarri | D24: Conner | E24: DL-LB-DB | F24: | | G24: KC | I24: ='2024_Roster_Offseason'!$C24&'2024_Roster_Offseason'!$D24 -> ChamarriConner | J24: 0.15 | K24: 0.07 | L24: 16 | M24: 21.4 | N24: 0 | O24: {=INDEX('2024_Transactions'!$J$2:$J$339,MATCH(1,('2024_Transactions'!$C$2:$C$339='2024_Roster_Offseason'!$I24)*('2024_Roster_Offseason'!$A24='2024_Transactions'!$B$2:$B$339),0))} -> Signed | P24: {=IFERROR(INDEX('2024_Draft_team'!$J$2:$J$271,MATCH(1,('2024_Roster_Offseason'!$I24='2024_Draft_team'!$Q$2:$Q$271)*('2024_Roster_Offseason'!$A24='2024_Draft_team'!$B$2:$B$271),0)),15)} -> 15 | Q24: N
A25: Box of Rocks | B25: DL-LB-DB | C25: Brandon | D25: Jones | E25: DL-LB-DB | F25: | | G25: DEN | I25: ='2024_Roster_Offseason'!$C25&'2024_Roster_Offseason'!$D25 -> BrandonJones | J25: 0.73 | K25: 0.58 | L25: 0 | M25: 22.62 | N25: 0 | O25: {=INDEX('2024_Transactions'!$J$2:$J$339,MATCH(1,('2024_Transactions'!$C$2:$C$339='2024_Roster_Offseason'!$I25)*('2024_Roster_Offseason'!$A25='2024_Transactions'!$B$2:$B$339),0))} -> Signed | P25: {=IFERROR(INDEX('2024_Draft_team'!$J$2:$J$271,MATCH(1,('2024_Roster_Offseason'!$I25='2024_Draft_team'!$Q$2:$Q$271)*('2024_Roster_Offseason'!$A25='2024_Draft_team'!$B$2:$B$271),0)),15)} -> 15 | Q25: N
A26: Box of Rocks | B26: DL-LB-DB | C26: Jaylon | D26: Jones | E26: DL-LB-DB | F26: | | G26: IND | I26: ='2024_Roster_Offseason'!$C26&'2024_Roster_Offseason'!$D26 -> JaylonJones | J26: 0.2 | K26: 0.06 | L26: 0 | M26: 17.24 | N26: 0 | O26: {=INDEX('2024_Transactions'!$J$2:$J$339,MATCH(1,('2024_Transactions'!$C$2:$C$339='2024_Roster_Offseason'!$I26)*('2024_Roster_Offseason'!$A26='2024_Transactions'!$B$2:$B$339),0))} -> Signed | P26: {=IFERROR(INDEX('2024_Draft_team'!$J$2:$J$271,MATCH(1,('2024_Roster_Offseason'!$I26='2024_Draft_team'!$Q$2:$Q$271)*('2024_Roster_Offseason'!$A26='2024_Draft_team'!$B$2:$B$271),0)),15)} -> 15 | Q26: N
A27: Box of Rocks | B27: DL-LB-DB | C27: Kayvon | D27: Thibodeaux | E27: DL-LB-DB | F27: | | G27: NYG | I27: ='2024_Roster_Offseason'!$C27&'2024_Roster_Offseason'!$D27 -> KayvonThibodeaux | J27: 0.31 | K27: 0.17 | L27: 0 | M27: 11 | N27: 0 | O27: {=INDEX('2024_Transactions'!$J$2:$J$339,MATCH(1,('2024_Transactions'!$C$2:$C$339='2024_Roster_Offseason'!$I27)*('2024_Roster_Offseason'!$A27='2024_Transactions'!$B$2:$B$339),0))} -> #N/A | P27: {=INDEX('2024_Draft_team'!$J$2:$J$271,MATCH(1,('2024_Roster_Offseason'!$I27='2024_Draft_team'!$Q$2:$Q$271)*('2024_Roster_Offseason'!$A27='2024_Draft_team'!$B$2:$B$271),0))} -> 7 | Q27: N
A28: Box of Rocks | B28: DL-LB-DB | C28: Devon | D28: Witherspoon | E28: DL-LB-DB | F28: | | G28: SEA | I28: ='2024_Roster_Offseason'!$C28&'2024_Roster_Offseason'!$D28 -> DevonWitherspoon | J28: 0.4 | K28: 0.27 | L28: 0 | M28: 15.94 | N28: 0 | O28: {=INDEX('2024_Transactions'!$J$2:$J$339,MATCH(1,('2024_Transactions'!$C$2:$C$339='2024_Roster_Offseason'!$I28)*('2024_Roster_Offseason'!$A28='2024_Transactions'!$B$2:$B$339),0))} -> #N/A | P28: {=INDEX('2024_Draft_team'!$J$2:$J$271,MATCH(1,('2024_Roster_Offseason'!$I28='2024_Draft_team'!$Q$2:$Q$271)*('2024_Roster_Offseason'!$A28='2024_Draft_team'!$B$2:$B$271),0))} -> 18 | Q28: Y
A29: Box of Rocks | B29: QB | C29: Dak | D29: Prescott | E29: QB | F29: | | G29: DAL | I29: ='2024_Roster_Offseason'!$C29&'2024_Roster_Offseason'!$D29 -> DakPrescott | J29: 0.2 | K29: 0.03 | L29: 0 | M29: 33.88 | N29: 0 | O29: {=INDEX('2024_Transactions'!$J$2:$J$339,MATCH(1,('2024_Transactions'!$C$2:$C$339='2024_Roster_Offseason'!$I29)*('2024_Roster_Offseason'!$A29='2024_Transactions'!$B$2:$B$339),0))} -> #N/A | P29: {=INDEX('2024_Draft_team'!$J$2:$J$271,MATCH(1,('2024_Roster_Offseason'!$I29='2024_Draft_team'!$Q$2:$Q$271)*('2024_Roster_Offseason'!$A29='2024_Draft_team'!$B$2:$B$271),0))} -> N/A | Q29: N
A30: Box of Rocks | B30: RB | C30: Christian | D30: McCaffrey | E30: RB | F30: | | G30: SF | I30: ='2024_Roster_Offseason'!$C30&'2024_Roster_Offseason'!$D30 -> ChristianMcCaffrey | J30: 0.58 | K30: 0.07 | L30: 0 | M30: 16 | N30: 0 | O30: {=INDEX('2024_Transactions'!$J$2:$J$339,MATCH(1,('2024_Transactions'!$C$2:$C$339='2024_Roster_Offseason'!$I30)*('2024_Roster_Offseason'!$A30='2024_Transactions'!$B$2:$B$339),0))} -> #N/A | P30: {=INDEX('2024_Draft_team'!$J$2:$J$271,MATCH(1,('2024_Roster_Offseason'!$I30='2024_Draft_team'!$Q$2:$Q$271)*('2024_Roster_Offseason'!$A30='2024_Draft_team'!$B$2:$B$271),0))} -> N/A | Q30: N
A31: Box of Rocks | B31: WR-TE | C31: Rashid | D31: Shaheed | E31: WR-TE | F31: | | G31: NO | I31: ='2024_Roster_Offseason'!$C31&'2024_Roster_Offseason'!$D31 -> RashidShaheed | J31: 0.15 | K31: 0.01 | L31: 0 | M31: 21 | N31: 0 | O31: {=INDEX('2024_Transactions'!$J$2:$J$339,MATCH(1,('2024_Transactions'!$C$2:$C$339='2024_Roster_Offseason'!$I31)*('2024_Roster_Offseason'!$A31='2024_Transactions'!$B$2:$B$339),0))} -> Signed | P31: {=IFERROR(INDEX('2024_Draft_team'!$J$2:$J$271,MATCH(1,('2024_Roster_Offseason'!$I31='2024_Draft_team'!$Q$2:$Q$271)*('2024_Roster_Offseason'!$A31='2024_Draft_team'!$B$2:$B$271),0)),15)} -> 15 | Q31: N
A32: Box of Rocks | B32: DL-LB-DB | C32: Daxton | D32: Hill | E32: DL-LB-DB | F32: | | G32: CIN | I32: ='2024_Roster_Offseason'!$C32&'2024_Roster_Offseason'!$D32 -> DaxtonHill | J32: 0.07 | K32: 0.01 | L32: 0 | M32: 16.2 | N32: 0 | O32: {=INDEX('2024_Transactions'!$J$2:$J$339,MATCH(1,('2024_Transactions'!$C$2:$C$339='2024_Roster_Offseason'!$I32)*('2024_Roster_Offseason'!$A32='2024_Transactions'!$B$2:$B$339),0))} -> #N/A | P32: {=INDEX('2024_Draft_team'!$J$2:$J$271,MATCH(1,('2024_Roster_Offseason'!$I32='2024_Draft_team'!$Q$2:$Q$271)*('2024_Roster_Offseason'!$A32='2024_Draft_team'!$B$2:$B$271),0))} -> 24 | Q32: N
A33: Box of Rocks | B33: DL-LB-DB | C33: Alex | D33: Singleton | E33: DL-LB-DB | F33: | | G33: DEN | I33: ='2024_Roster_Offseason'!$C33&'2024_Roster_Offseason'!$D33 -> AlexSingleton | J33: 0.23 | K33: 0.03 | L33: 0 | M33: 28 | N33: 0 | O33: {=INDEX('2024_Transactions'!$J$2:$J$339,MATCH(1,('2024_Transactions'!$C$2:$C$339='2024_Roster_Offseason'!$I33)*('2024_Roster_Offseason'!$A33='2024_Transactions'!$B$2:$B$339),0))} -> #N/A | P33: {=INDEX('2024_Draft_team'!$J$2:$J$271,MATCH(1,('2024_Roster_Offseason'!$I33='2024_Draft_team'!$Q$2:$Q$271)*('2024_Roster_Offseason'!$A33='2024_Draft_team'!$B$2:$B$271),0))} -> 4 | Q33: N
A34: Discount Belichick | B34: QB | C34: Jalen | D34: Hurts | E34: QB | F34: | | G34: PHI | I34: ='2024_Roster_Offseason'!$C34&'2024_Roster_Offseason'!$D34 -> JalenHurts | J34: 0.97 | K34: 0.59 | L34: 58 | M34: 57.13 | N34: 0 | O34: {=INDEX('2024_Transactions'!$J$2:$J$339,MATCH(1,('2024_Transactions'!$C$2:$C$339='2024_Roster_Offseason'!$I34)*('2024_Roster_Offseason'!$A34='2024_Transactions'!$B$2:$B$339),0))} -> #N/A | P34: {=INDEX('2024_Draft_team'!$J$2:$J$271,MATCH(1,('2024_Roster_Offseason'!$I34='2024_Draft_team'!$Q$2:$Q$271)*('2024_Roster_Offseason'!$A34='2024_Draft_team'!$B$2:$B$271),0))} -> N/A | Q34: N
A35: Discount Belichick | B35: QB | C35: Bo | D35: Nix | E35: QB | F35: | | G35: DEN | I35: ='2024_Roster_Offseason'!$C35&'2024_Roster_Offseason'!$D35 -> BoNix | J35: 0.95 | K35: 0.5 | L35: 0 | M35: 43.76 | N35: 0 | O35: {=INDEX('2024_Transactions'!$J$2:$J$339,MATCH(1,('2024_Transactions'!$C$2:$C$339='2024_Roster_Offseason'!$I35)*('2024_Roster_Offseason'!$A35='2024_Transactions'!$B$2:$B$339),0))} -> #N/A | P35: {=INDEX('2024_Draft_team'!$J$2:$J$271,MATCH(1,('2024_Roster_Offseason'!$I35='2024_Draft_team'!$Q$2:$Q$271)*('2024_Roster_Offseason'!$A35='2024_Draft_team'!$B$2:$B$271),0))} -> 22 | Q35: Y
A36: Discount Belichick | B36: RB | C36: Breece | D36: Hall | E36: RB | F36: | | G36: NYJ | I36: ='2024_Roster_Offseason'!$C36&'2024_Roster_Offseason'!$D36 -> BreeceHall | J36: 0.99 | K36: 0.67 | L36: 0 | M36: 21.94 | N36: 0 | O36: {=INDEX('2024_Transactions'!$J$2:$J$339,MATCH(1,('2024_Transactions'!$C$2:$C$339='2024_Roster_Offseason'!$I36)*('2024_Roster_Offseason'!$A36='2024_Transactions'!$B$2:$B$339),0))} -> #N/A | P36: {=INDEX('2024_Draft_team'!$J$2:$J$271,MATCH(1,('2024_Roster_Offseason'!$I36='2024_Draft_team'!$Q$2:$Q$271)*('2024_Roster_Offseason'!$A36='2024_Draft_team'!$B$2:$B$271),0))} -> 4 | Q36: Y
A37: Discount Belichick | B37: RB | C37: Tyrone | D37: Tracy | E37: Jr. | F37: RB | G37: | | H37: NYG | I37: ='2024_Roster_Offseason'!$C37&'2024_Roster_Offseason'!$D37&'2024_Roster_Offseason'!$E37 -> TyroneTracyJr. | J37: 0.95 | K37: 0.48 | L37: 0 | M37: 16.06 | N37: 0 | O37: {=INDEX('2024_Transactions'!$J$2:$J$339,MATCH(1,('2024_Transactions'!$C$2:$C$339='2024_Roster_Offseason'!$I37)*('2024_Roster_Offseason'!$A37='2024_Transactions'!$B$2:$B$339),0))} -> #N/A | P37: {=INDEX('2024_Draft_team'!$J$2:$J$271,MATCH(1,('2024_Roster_Offseason'!$I37='2024_Draft_team'!$Q$2:$Q$271)*('2024_Roster_Offseason'!$A37='2024_Draft_team'!$B$2:$B$271),0))} -> 25 | Q37: Y
A38: Discount Belichick | B38: WR-TE | C38: Brock | D38: Bowers | E38: WR-TE | F38: | | G38: LV | I38: ='2024_Roster_Offseason'!$C38&'2024_Roster_Offseason'!$D38 -> BrockBowers | J38: 0.99 | K38: 0.94 | L38: 0 | M38: 23.53 | N38: 0 | O38: {=INDEX('2024_Transactions'!$J$2:$J$339,MATCH(1,('2024_Transactions'!$C$2:$C$339='2024_Roster_Offseason'!$I38)*('2024_Roster_Offseason'!$A38='2024_Transactions'!$B$2:$B$339),0))} -> #N/A | P38: {=INDEX('2024_Draft_team'!$J$2:$J$271,MATCH(1,('2024_Roster_Offseason'!$I38='2024_Draft_team'!$Q$2:$Q$271)*('2024_Roster_Offseason'!$A38='2024_Draft_team'!$B$2:$B$271),0))} -> 23 | Q38: Y
A39: Discount Belichick | B39: WR-TE | C39: A.J. | D39: Brown | E39: WR-TE | F39: | | G39: PHI | I39: ='2024_Roster_Offseason'!$C39&'2024_Roster_Offseason'!$D39 -> A.J.Brown | J39: 1 | K39: 0.89 | L39: 23 | M39: 31.38 | N39: 0 | O39: {=INDEX('2024_Transactions'!$J$2:$J$339,MATCH(1,('2024_Transactions'!$C$2:$C$339='2024_Roster_Offseason'!$I39)*('2024_Roster_Offseason'!$A39='2024_Transactions'!$B$2:$B$339),0))} -> #N/A | P39: {=INDEX('2024_Draft_team'!$J$2:$J$271,MATCH(1,('2024_Roster_Offseason'!$I39='2024_Draft_team'!$Q$2:$Q$271)*('2024_Roster_Offseason'!$A39='2024_Draft_team'!$B$2:$B$271),0))} -> N/A | Q39: N
A40: Discount Belichick | B40: WR-TE | C40: Cooper | D40: Kupp | E40: WR-TE | F40: | | G40: LAR | I40: ='2024_Roster_Offseason'!$C40&'2024_Roster_Offseason'!$D40 -> CooperKupp | J40: 0.99 | K40: 0.79 | L40: 0 | M40: 25.25 | N40: 0 | O40: {=INDEX('2024_Transactions'!$J$2:$J$339,MATCH(1,('2024_Transactions'!$C$2:$C$339='2024_Roster_Offseason'!$I40)*('2024_Roster_Offseason'!$A40='2024_Transactions'!$B$2:$B$339),0))} -> #N/A | P40: {=INDEX('2024_Draft_team'!$J$2:$J$271,MATCH(1,('2024_Roster_Offseason'!$I40='2024_Draft_team'!$Q$2:$Q$271)*('2024_Roster_Offseason'!$A40='2024_Draft_team'!$B$2:$B$271),0))} -> 2 | Q40: N
...

Sheet 2024_Transactions
A1: Date | B1: Team | C1: PlayerMatch | D1: First | E1: Last | F1: Position | G1: Break | H1: Team2 | I1: N/A | J1: Type
A2: 12/29/24 12:38 PM ET | B2: Let Bijans be Bijans | C2: =+'2024_Transactions'!$D2&'2024_Transactions'!$E2 -> MaristLiufau | D2: Marist | E2: Liufau | F2: LB | G2: | | H2: DAL | I2: - | J2: Dropped
A3: 12/29/24 3:16 AM ET | B3: Sweet Chin Music | C3: =+'2024_Transactions'!$D3&'2024_Transactions'!$E3 -> JalenMcMillan | D3: Jalen | E3: McMillan | F3: WR | G3: | | H3: TB | I3: - | J3: Signed
A4: 12/29/24 3:16 AM ET | B4: Sweet Chin Music | C4: =+'2024_Transactions'!$D4&'2024_Transactions'!$E4 -> MilesSanders | D4: Miles | E4: Sanders | F4: RB | G4: | | H4: CAR | I4: - | J4: Signed
A5: 12/28/24 9:09 AM ET | B5: Sweet Chin Music | C5: =+'2024_Transactions'!$D5&'2024_Transactions'!$E5 -> TylerAllgeier | D5: Tyler | E5: Allgeier | F5: RB | G5: | | H5: ATL | I5: - | J5: Dropped
A6: 12/28/24 1:45 AM ET | B6: Fields of Dreams | C6: =+'2024_Transactions'!$D6&'2024_Transactions'!$E6 -> DrewSanders | D6: Drew | E6: Sanders | F6: LB | G6: | | H6: DEN | I6: - | J6: Signed
A7: 12/28/24 1:45 AM ET | B7: Fields of Dreams | C7: =+'2024_Transactions'!$D7&'2024_Transactions'!$E7 -> TySummers | D7: Ty | E7: Summers | F7: LB | G7: | | H7: NYG | I7: - | J7: Signed
A8: 12/28/24 1:45 AM ET | B8: Sweet Chin Music | C8: =+'2024_Transactions'!$D8&'2024_Transactions'!$E8 -> JacobyWindmon | D8: Jacoby | E8: Windmon | F8: LB | G8: | | H8: CAR | I8: - | J8: Signed
A9: 12/26/24 1:46 AM ET | B9: Fields of Dreams | C9: =+'2024_Transactions'!$D9&'2024_Transactions'!$E9 -> DaRonBland | D9: DaRon | E9: Bland | F9: DB | G9: | | H9: DAL | I9: - | J9: Signed
A10: 12/26/24 1:46 AM ET | B10: Fields of Dreams | C10: =+'2024_Transactions'!$D10&'2024_Transactions'!$E10 -> CedricGray | D10: Cedric | E10: Gray | F10: LB | G10: | | H10: TEN | I10: - | J10: Signed
A11: 12/25/24 10:52 AM ET | B11: Fields of Dreams | C11: =+'2024_Transactions'!$D11&'2024_Transactions'!$E11 -> NevilleHewitt | D11: Neville | E11: Hewitt | F11: LB | G11: | | H11: HOU | I11: - | J11: Dropped
A12: 12/22/24 9:18 AM ET | B12: The Bushwhackers | C12: =+'2024_Transactions'!$D12&'2024_Transactions'!$E12 -> DonovanWilson | D12: Donovan | E12: Wilson | F12: DB | G12: | | H12: DAL | I12: - | J12: Signed
A13: 12/22/24 7:15 AM ET | B13: Fields of Dreams | C13: =+'2024_Transactions'!$D13&'2024_Transactions'!$E13 -> TyjaeSpears | D13: Tyjae | E13: Spears | F13: RB | G13: | | H13: TEN | I13: - | J13: Signed
... A339: 5/8/24 1:42 PM ET | B339: Go Go Garrett | C339: =+'2024_Transactions'!$D339&'2024_Transactions'!$E339 -> RasheeRice | D339: Rashee | E339: Rice | F339: WR | G339: | | H339: KC | I339: - | J339: Dropped
A340: red = Transaction performed by commissioner

Sheet 2024_Draft_team
A1: Rnd/Pk | B1: Team | C1: Player | D1: Elapsed Time | E1: Rank | F1: Total Fpts | G1: Active Fpts | H1: Keeper | I1: 2024Round | J1: 2025Round | K1: First | L1: Last | M1: Position | N1: Blank | O1: Team2 | P1: Column6 | Q1: PlayerMatch | R1: Dropped
A2: 1/1 | B2: Gatordontplay | C2: Jared Goff QB | DET (Keeper) | E2: #8 QB | F2: 756 | G2: 710 | H2: =(RIGHT('2024_Draft_team'!$C2,8)="(Keeper)") -> TRUE | I2: =IF(RIGHT(LEFT('2024_Draft_team'!$A2,3))="/",RIGHT(LEFT('2024_Draft_team'!$A2,2),1),RIGHT(LEFT('2024_Draft_team'!$A2,3),2)) -> 1 | J2: =IF(OR(AND(('2024_Draft_team'!$I2-4)<=0,'2024_Draft_team'!$H2=TRUE),('2024_Draft_team'!$R2=TRUE)),"N/A",IF('2024_Draft_team'!$H2=TRUE,'2024_Draft_team'!$I2-4,'2024_Draft_team'!$I2-0)) -> N/A | K2: Jared | L2: Goff | M2: QB | N2: | | O2: DET | P2: (Keeper) | Q2: ='2024_Draft_team'!$K2&'2024_Draft_team'!$L2 -> JaredGoff | R2: {=IFERROR((INDEX('2024_Transactions'!$J$2:$J$339,MATCH(1,('2024_Draft_team'!$Q2='2024_Transactions'!$C$2:$C$339)*('2024_Draft_team'!$B2='2024_Transactions'!$B$2:$B$339)*('2024_Transactions'!$J$2:$J$339="Dropped"),0))="Dropped"),FALSE)} -> FALSE
A3: 2/1 | B3: Gatordontplay | C3: Marvin Harrison Jr. WR | ARI | D3: 8 min 19 sec | E3: #32 WR | F3: 329 | G3: 253 | H3: =(RIGHT('2024_Draft_team'!$C3,8)="(Keeper)") -> FALSE | I3: =IF(RIGHT(LEFT('2024_Draft_team'!$A3,3))="/",RIGHT(LEFT('2024_Draft_team'!$A3,2),1),RIGHT(LEFT('2024_Draft_team'!$A3,3),2)) -> 2 | J3: =IF(OR(AND(('2024_Draft_team'!$I3-4)<=0,'2024_Draft_team'!$H3=TRUE),('2024_Draft_team'!$R3=TRUE)),"N/A",IF('2024_Draft_team'!$H3=TRUE,'2024_Draft_team'!$I3-4,'2024_Draft_team'!$I3-0)) -> 2 | K3: Marvin | L3: Harrison | M3: Jr. | N3: WR | O3: | | P3: ARI | Q3: ='2024_Draft_team'!$K3&'2024_Draft_team'!$L3&'2024_Draft_team'!$M3 -> MarvinHarrisonJr. | R3: {=IFERROR((INDEX('2024_Transactions'!$J$2:$J$339,MATCH(1,('2024_Draft_team'!$Q3='2024_Transactions'!$C$2:$C$339)*('2024_Draft_team'!$B3='2024_Transactions'!$B$2:$B$339)*('2024_Transactions'!$J$2:$J$339="Dropped"),0))="Dropped"),FALSE)} -> FALSE
A4: 3/1 | B4: Gatordontplay | C4: Derrick Henry RB | BAL (Keeper) | D4: 0 sec | E4: #2 RB | F4: 666 | G4: 533 | H4: =(RIGHT('2024_Draft_team'!$C4,8)="(Keeper)") -> TRUE | I4: =IF(RIGHT(LEFT('2024_Draft_team'!$A4,3))="/",RIGHT(LEFT('2024_Draft_team'!$A4,2),1),RIGHT(LEFT('2024_Draft_team'!$A4,3),2)) -> 3 | J4: =IF(OR(AND(('2024_Draft_team'!$I4-4)<=0,'2024_Draft_team'!$H4=TRUE),('2024_Draft_team'!$R4=TRUE)),"N/A",IF('2024_Draft_team'!$H4=TRUE,'2024_Draft_team'!$I4-4,'2024_Draft_team'!$I4-0)) -> N/A | K4: Derrick | L4: Henry | M4: RB | N4: | | O4: BAL | P4: (Keeper) | Q4: ='2024_Draft_team'!$K4&'2024_Draft_team'!$L4 -> DerrickHenry | R4: {=IFERROR((INDEX('2024_Transactions'!$J$2:$J$339,MATCH(1,('2024_Draft_team'!$Q4='2024_Transactions'!$C$2:$C$339)*('2024_Draft_team'!$B4='2024_Transactions'!$B$2:$B$339)*('2024_Transactions'!$J$2:$J$339="Dropped"),0))="Dropped"),FALSE)} -> FALSE
A5: 4/1 | B5: Gatordontplay | C5: Travis Kelce TE | KC (Keeper) | D5: 0 sec | E5: #5 TE | F5: 369 | G5: 264 | H5: =(RIGHT('2024_Draft_team'!$C5,8)="(Keeper)") -> TRUE | I5: =IF(RIGHT(LEFT('2024_Draft_team'!$A5,3))="/",RIGHT(LEFT('2024_Draft_team'!$A5,2),1),RIGHT(LEFT('2024_Draft_team'!$A5,3),2)) -> 4 | J5: =IF(OR(AND(('2024_Draft_team'!$I5-4)<=0,'2024_Draft_team'!$H5=TRUE),('2024_Draft_team'!$R5=TRUE)),"N/A",IF('2024_Draft_team'!$H5=TRUE,'2024_Draft_team'!$I5-4,'2024_Draft_team'!$I5-0)) -> N/A | K5: Travis | L5: Kelce | M5: TE | N5: | | O5: KC | P5: (Keeper) | Q5: ='2024_Draft_team'!$K5&'2024_Draft_team'!$L5 -> TravisKelce | R5: {=IFERROR((INDEX('2024_Transactions'!$J$2:$J$339,MATCH(1,('2024_Draft_team'!$Q5='2024_Transactions'!$C$2:$C$339)*('2024_Draft_team'!$B5='2024_Transactions'!$B$2:$B$339)*('2024_Transactions'!$J$2:$J$339="Dropped"),0))="Dropped"),FALSE)} -> FALSE
A6: 5/1 | B6: Gatordontplay | C6: Aaron Jones RB | MIN (Keeper) | D6: 0 sec | E6: #16 RB | F6: 382 | G6: 266 | H6: =(RIGHT('2024_Draft_team'!$C6,8)="(Keeper)") -> TRUE | I6: =IF(RIGHT(LEFT('2024_Draft_team'!$A6,3))="/",RIGHT(LEFT('2024_Draft_team'!$A6,2),1),RIGHT(LEFT('2024_Draft_team'!$A6,3),2)) -> 5 | J6: =IF(OR(AND(('2024_Draft_team'!$I6-4)<=0,'2024_Draft_team'!$H6=TRUE),('2024_Draft_team'!$R6=TRUE)),"N/A",IF('2024_Draft_team'!$H6=TRUE,'2024_Draft_team'!$I6-4,'2024_Draft_team'!$I6-0)) -> 1 | K6: Aaron | L6: Jones | M6: RB | N6: | | O6: MIN | P6: (Keeper) | Q6: ='2024_Draft_team'!$K6&'2024_Draft_team'!$L6 -> AaronJones | R6: {=IFERROR((INDEX('2024_Transactions'!$J$2:$J$339,MATCH(1,('2024_Draft_team'!$Q6='2024_Transactions'!$C$2:$C$339)*('2024_Draft_team'!$B6='2024_Transactions'!$B$2:$B$339)*('2024_Transactions'!$J$2:$J$339="Dropped"),0))="Dropped"),FALSE)} -> FALSE
A7: 6/1 | B7: Gatordontplay | C7: Drue Tranquill LB | KC (Keeper) | D7: 0 sec | E7: #34 LB | F7: 302 | G7: 238 | H7: =(RIGHT('2024_Draft_team'!$C7,8)="(Keeper)") -> TRUE | I7: =IF(RIGHT(LEFT('2024_Draft_team'!$A7,3))="/",RIGHT(LEFT('2024_Draft_team'!$A7,2),1),RIGHT(LEFT('2024_Draft_team'!$A7,3),2)) -> 6 | J7: =IF(OR(AND(('2024_Draft_team'!$I7-4)<=0,'2024_Draft_team'!$H7=TRUE),('2024_Draft_team'!$R7=TRUE)),"N/A",IF('2024_Draft_team'!$H7=TRUE,'2024_Draft_team'!$I7-4,'2024_Draft_team'!$I7-0)) -> 2 | K7: Drue | L7: Tranquill | M7: LB | N7: | | O7: KC | P7: (Keeper) | Q7: ='2024_Draft_team'!$K7&'2024_Draft_team'!$L7 -> DrueTranquill | R7: {=IFERROR((INDEX('2024_Transactions'!$J$2:$J$339,MATCH(1,('2024_Draft_team'!$Q7='2024_Transactions'!$C$2:$C$339)*('2024_Draft_team'!$B7='2024_Transactions'!$B$2:$B$339)*('2024_Transactions'!$J$2:$J$339="Dropped"),0))="Dropped"),FALSE)} -> FALSE
A8: 7/1 | B8: Gatordontplay | C8: Deebo Samuel WR | SF (Keeper) | D8: 0 sec | E8: #46 WR | F8: 257 | G8: 131 | H8: =(RIGHT('2024_Draft_team'!$C8,8)="(Keeper)") -> TRUE | I8: =IF(RIGHT(LEFT('2024_Draft_team'!$A8,3))="/",RIGHT(LEFT('2024_Draft_team'!$A8,2),1),RIGHT(LEFT('2024_Draft_team'!$A8,3),2)) -> 7 | J8: =IF(OR(AND(('2024_Draft_team'!$I8-4)<=0,'2024_Draft_team'!$H8=TRUE),('2024_Draft_team'!$R8=TRUE)),"N/A",IF('2024_Draft_team'!$H8=TRUE,'2024_Draft_team'!$I8-4,'2024_Draft_team'!$I8-0)) -> 3 | K8: Deebo | L8: Samuel | M8: WR | N8: | | O8: SF | P8: (Keeper) | Q8: ='2024_Draft_team'!$K8&'2024_Draft_team'!$L8 -> DeeboSamuel | R8: {=IFERROR((INDEX('2024_Transactions'!$J$2:$J$339,MATCH(1,('2024_Draft_team'!$Q8='2024_Transactions'!$C$2:$C$339)*('2024_Draft_team'!$B8='2024_Transactions'!$B$2:$B$339)*('2024_Transactions'!$J$2:$J$339="Dropped"),0))="Dropped"),FALSE)} -> FALSE
A9: 8/1 | B9: Gatordontplay | C9: Jaylen Waddle WR | MIA (Keeper) | D9: 0 sec | E9: #49 WR | F9: 241 | G9: 57 | H9: =(RIGHT('2024_Draft_team'!$C9,8)="(Keeper)") -> TRUE | I9: =IF(RIGHT(LEFT('2024_Draft_team'!$A9,3))="/",RIGHT(LEFT('2024_Draft_team'!$A9,2),1),RIGHT(LEFT('2024_Draft_team'!$A9,3),2)) -> 8 | J9: =IF(OR(AND(('2024_Draft_team'!$I9-4)<=0,'2024_Draft_team'!$H9=TRUE),('2024_Draft_team'!$R9=TRUE)),"N/A",IF('2024_Draft_team'!$H9=TRUE,'2024_Draft_team'!$I9-4,'2024_Draft_team'!$I9-0)) -> 4 | K9: Jaylen | L9: Waddle | M9: WR | N9: | | O9: MIA | P9: (Keeper) | Q9: ='2024_Draft_team'!$K9&'2024_Draft_team'!$L9 -> JaylenWaddle | R9: {=IFERROR((INDEX('2024_Transactions'!$J$2:$J$339,MATCH(1,('2024_Draft_team'!$Q9='2024_Transactions'!$C$2:$C$339)*('2024_Draft_team'!$B9='2024_Transactions'!$B$2:$B$339)*('2024_Transactions'!$J$2:$J$339="Dropped"),0))="Dropped"),FALSE)} -> FALSE
A10: 9/1 | B10: Gatordontplay | C10: Eddie Jackson DB | LAC (Keeper) | D10: 0 sec | E10: #225 DB | F10: 73 | G10: 38 | H10: =(RIGHT('2024_Draft_team'!$C10,8)="(Keeper)") -> TRUE | I10: =IF(RIGHT(LEFT('2024_Draft_team'!$A10,3))="/",RIGHT(LEFT('2024_Draft_team'!$A10,2),1),RIGHT(LEFT('2024_Draft_team'!$A10,3),2)) -> 9 | J10: =IF(OR(AND(('2024_Draft_team'!$I10-4)<=0,'2024_Draft_team'!$H10=TRUE),('2024_Draft_team'!$R10=TRUE)),"N/A",IF('2024_Draft_team'!$H10=TRUE,'2024_Draft_team'!$I10-4,'2024_Draft_team'!$I10-0)) -> N/A | K10: Eddie | L10: Jackson | M10: DB | N10: | | O10: LAC | P10: (Keeper) | Q10: ='2024_Draft_team'!$K10&'2024_Draft_team'!$L10 -> EddieJackson | R10: {=IFERROR((INDEX('2024_Transactions'!$J$2:$J$339,MATCH(1,('2024_Draft_team'!$Q10='2024_Transactions'!$C$2:$C$339)*('2024_Draft_team'!$B10='2024_Transactions'!$B$2:$B$339)*('2024_Transactions'!$J$2:$J$339="Dropped"),0))="Dropped"),FALSE)} -> TRUE
A11: 10/1 | B11: Gatordontplay | C11: Tony Pollard RB | TEN | D11: 10 hrs 45 min 33 sec | E11: #21 RB | F11: 317 | G11: 98 | H11: =(RIGHT('2024_Draft_team'!$C11,8)="(Keeper)") -> FALSE | I11: =IF(RIGHT(LEFT('2024_Draft_team'!$A11,3))="/",RIGHT(LEFT('2024_Draft_team'!$A11,2),1),RIGHT(LEFT('2024_Draft_team'!$A11,3),2)) -> 10 | J11: =IF(OR(AND(('2024_Draft_team'!$I11-4)<=0,'2024_Draft_team'!$H11=TRUE),('2024_Draft_team'!$R11=TRUE)),"N/A",IF('2024_Draft_team'!$H11=TRUE,'2024_Draft_team'!$I11-4,'2024_Draft_team'!$I11-0)) -> 10 | K11: Tony | L11: Pollard | M11: RB | N11: | | O11: TEN | Q11: ='2024_Draft_team'!$K11&'2024_Draft_team'!$L11 -> TonyPollard | R11: {=IFERROR((INDEX('2024_Transactions'!$J$2:$J$339,MATCH(1,('2024_Draft_team'!$Q11='2024_Transactions'!$C$2:$C$339)*('2024_Draft_team'!$B11='2024_Transactions'!$B$2:$B$339)*('2024_Transactions'!$J$2:$J$339="Dropped"),0))="Dropped"),FALSE)} -> FALSE
A12: 11/1 | B12: Gatordontplay | C12: Lavonte David LB | TB (Keeper) | D12: 1 sec | E12: #6 LB | F12: 403 | G12: 360 | H12: =(RIGHT('2024_Draft_team'!$C12,8)="(Keeper)") -> TRUE | I12: =IF(RIGHT(LEFT('2024_Draft_team'!$A12,3))="/",RIGHT(LEFT('2024_Draft_team'!$A12,2),1),RIGHT(LEFT('2024_Draft_team'!$A12,3),2)) -> 11 | J12: =IF(OR(AND(('2024_Draft_team'!$I12-4)<=0,'2024_Draft_team'!$H12=TRUE),('2024_Draft_team'!$R12=TRUE)),"N/A",IF('2024_Draft_team'!$H12=TRUE,'2024_Draft_team'!$I12-4,'2024_Draft_team'!$I12-0)) -> 7 | K12: Lavonte | L12: David | M12: LB | N12: | | O12: TB | P12: (Keeper) | Q12: ='2024_Draft_team'!$K12&'2024_Draft_team'!$L12 -> LavonteDavid | R12: {=IFERROR((INDEX('2024_Transactions'!$J$2:$J$339,MATCH(1,('2024_Draft_team'!$Q12='2024_Transactions'!$C$2:$C$339)*('2024_Draft_team'!$B12='2024_Transactions'!$B$2:$B$339)*('2024_Transactions'!$J$2:$J$339="Dropped"),0))="Dropped"),FALSE)} -> FALSE
A13: 12/1 | B13: Gatordontplay | C13: Antoine Winfield Jr. DB | TB (Keeper) | D13: 0 sec | E13: #120 DB | F13: 183 | G13: 170 | H13: =(RIGHT('2024_Draft_team'!$C13,8)="(Keeper)") -> TRUE | I13: =IF(RIGHT(LEFT('2024_Draft_team'!$A13,3))="/",RIGHT(LEFT('2024_Draft_team'!$A13,2),1),RIGHT(LEFT('2024_Draft_team'!$A13,3),2)) -> 12 | J13: =IF(OR(AND(('2024_Draft_team'!$I13-4)<=0,'2024_Draft_team'!$H13=TRUE),('2024_Draft_team'!$R13=TRUE)),"N/A",IF('2024_Draft_team'!$H13=TRUE,'2024_Draft_team'!$I13-4,'2024_Draft_team'!$I13-0)) -> 8 | K13: Antoine | L13: Winfield | M13: Jr. | N13: DB | O13: | | P13: TB | Q13: ='2024_Draft_team'!$K13&'2024_Draft_team'!$L13&'2024_Draft_team'!$M13 -> AntoineWinfieldJr. | R13: {=IFERROR((INDEX('2024_Transactions'!$J$2:$J$339,MATCH(1,('2024_Draft_team'!$Q13='2024_Transactions'!$C$2:$C$339)*('2024_Draft_team'!$B13='2024_Transactions'!$B$2:$B$339)*('2024_Transactions'!$J$2:$J$339="Dropped"),0))="Dropped"),FALSE)} -> FALSE
A14: 13/1 | B14: Gatordontplay | C14: Tyler Lockett WR | SEA (Keeper) | D14: 0 sec | E14: #64 WR | F14: 210 | G14: 42 | H14: =(RIGHT('2024_Draft_team'!$C14,8)="(Keeper)") -> TRUE | I14: =IF(RIGHT(LEFT('2024_Draft_team'!$A14,3))="/",RIGHT(LEFT('2024_Draft_team'!$A14,2),1),RIGHT(LEFT('2024_Draft_team'!$A14,3),2)) -> 13 | J14: =IF(OR(AND(('2024_Draft_team'!$I14-4)<=0,'2024_Draft_team'!$H14=TRUE),('2024_Draft_team'!$R14=TRUE)),"N/A",IF('2024_Draft_team'!$H14=TRUE,'2024_Draft_team'!$I14-4,'2024_Draft_team'!$I14-0)) -> 9 | K14: Tyler | L14: Lockett | M14: WR | N14: | | O14: SEA | P14: (Keeper) | Q14: ='2024_Draft_team'!$K14&'2024_Draft_team'!$L14 -> TylerLockett | R14: {=IFERROR((INDEX('2024_Transactions'!$J$2:$J$339,MATCH(1,('2024_Draft_team'!$Q14='2024_Transactions'!$C$2:$C$339)*('2024_Draft_team'!$B14='2024_Transactions'!$B$2:$B$339)*('2024_Transactions'!$J$2:$J$339="Dropped"),0))="Dropped"),FALSE)} -> FALSE
A15: 14/1 | B15: Gatordontplay | C15: Baker Mayfield QB | TB (Keeper) | D15: 0 sec | E15: #5 QB | F15: 870 | G15: 667 | H15: =(RIGHT('2024_Draft_team'!$C15,8)="(Keeper)") -> TRUE | I15: =IF(RIGHT(LEFT('2024_Draft_team'!$A15,3))="/",RIGHT(LEFT('2024_Draft_team'!$A15,2),1),RIGHT(LEFT('2024_Draft_team'!$A15,3),2)) -> 14 | J15: =IF(OR(AND(('2024_Draft_team'!$I15-4)<=0,'2024_Draft_team'!$H15=TRUE),('2024_Draft_team'!$R15=TRUE)),"N/A",IF('2024_Draft_team'!$H15=TRUE,'2024_Draft_team'!$I15-4,'2024_Draft_team'!$I15-0)) -> 10 | K15: Baker | L15: Mayfield | M15: QB | N15: | | O15: TB | P15: (Keeper) | Q15: ='2024_Draft_team'!$K15&'2024_Draft_team'!$L15 -> BakerMayfield | R15: {=IFERROR((INDEX('2024_Transactions'!$J$2:$J$339,MATCH(1,('2024_Draft_team'!$Q15='2024_Transactions'!$C$2:$C$339)*('2024_Draft_team'!$B15='2024_Transactions'!$B$2:$B$339)*('2024_Transactions'!$J$2:$J$339="Dropped"),0))="Dropped"),FALSE)} -> FALSE
A16: 15/1 | B16: Gatordontplay | C16: Aaron Rodgers QB | NYJ (Keeper) | D16: 0 sec | E16: #14 QB | F16: 597 | G16: 95 | H16: =(RIGHT('2024_Draft_team'!$C16,8)="(Keeper)") -> TRUE | I16: =IF(RIGHT(LEFT('2024_Draft_team'!$A16,3))="/",RIGHT(LEFT('2024_Draft_team'!$A16,2),1),RIGHT(LEFT('2024_Draft_team'!$A16,3),2)) -> 15 | J16: =IF(OR(AND(('2024_Draft_team'!$I16-4)<=0,'2024_Draft_team'!$H16=TRUE),('2024_Draft_team'!$R16=TRUE)),"N/A",IF('2024_Draft_team'!$H16=TRUE,'2024_Draft_team'!$I16-4,'2024_Draft_team'!$I16-0)) -> 11 | K16: Aaron | L16: Rodgers | M16: QB | N16: | | O16: NYJ | P16: (Keeper) | Q16: ='2024_Draft_team'!$K16&'2024_Draft_team'!$L16 -> AaronRodgers | R16: {=IFERROR((INDEX('2024_Transactions'!$J$2:$J$339,MATCH(1,('2024_Draft_team'!$Q16='2024_Transactions'!$C$2:$C$339)*('2024_Draft_team'!$B16='2024_Transactions'!$B$2:$B$339)*('2024_Transactions'!$J$2:$J$339="Dropped"),0))="Dropped"),FALSE)} -> FALSE
A17: 16/1 | B17: Gatordontplay | C17: Kamren Curl DB | LAR (Keeper) | D17: 0 sec | E17: #59 DB | F17: 241 | G17: 221 | H17: =(RIGHT('2024_Draft_team'!$C17,8)="(Keeper)") -> TRUE | I17: =IF(RIGHT(LEFT('2024_Draft_team'!$A17,3))="/",RIGHT(LEFT('2024_Draft_team'!$A17,2),1),RIGHT(LEFT('2024_Draft_team'!$A17,3),2)) -> 16 | J17: =IF(OR(AND(('2024_Draft_team'!$I17-4)<=0,'2024_Draft_team'!$H17=TRUE),('2024_Draft_team'!$R17=TRUE)),"N/A",IF('2024_Draft_team'!$H17=TRUE,'2024_Draft_team'!$I17-4,'2024_Draft_team'!$I17-0)) -> 12 | K17: Kamren | L17: Curl | M17: DB | N17: | | O17: LAR | P17: (Keeper) | Q17: ='2024_Draft_team'!$K17&'2024_Draft_team'!$L17 -> KamrenCurl | R17: {=IFERROR((INDEX('2024_Transactions'!$J$2:$J$339,MATCH(1,('2024_Draft_team'!$Q17='2024_Transactions'!$C$2:$C$339)*('2024_Draft_team'!$B17='2024_Transactions'!$B$2:$B$339)*('2024_Transactions'!$J$2:$J$339="Dropped"),0))="Dropped"),FALSE)} -> FALSE
A18: 17/1 | B18: Gatordontplay | C18: Rayshawn Jenkins DB | SEA (Keeper) | D18: 0 sec | E18: #143 DB | F18: 157 | G18: 102 | H18: =(RIGHT('2024_Draft_team'!$C18,8)="(Keeper)") -> TRUE | I18: =IF(RIGHT(LEFT('2024_Draft_team'!$A18,3))="/",RIGHT(LEFT('2024_Draft_team'!$A18,2),1),RIGHT(LEFT('2024_Draft_team'!$A18,3),2)) -> 17 | J18: =IF(OR(AND(('2024_Draft_team'!$I18-4)<=0,'2024_Draft_team'!$H18=TRUE),('2024_Draft_team'!$R18=TRUE)),"N/A",IF('2024_Draft_team'!$H18=TRUE,'2024_Draft_team'!$I18-4,'2024_Draft_team'!$I18-0)) -> N/A | K18: Rayshawn | L18: Jenkins | M18: DB | N18: | | O18: SEA | P18: (Keeper) | Q18: ='2024_Draft_team'!$K18&'2024_Draft_team'!$L18 -> RayshawnJenkins | R18: {=IFERROR((INDEX('2024_Transactions'!$J$2:$J$339,MATCH(1,('2024_Draft_team'!$Q18='2024_Transactions'!$C$2:$C$339)*('2024_Draft_team'!$B18='2024_Transactions'!$B$2:$B$339)*('2024_Transactions'!$J$2:$J$339="Dropped"),0))="Dropped"),FALSE)} -> TRUE
A19: 18/1 | B19: Gatordontplay | C19: Harrison Butker K | KC (Keeper) | D19: 0 sec | E19: #24 K | F19: 224 | G19: 153 | H19: =(RIGHT('2024_Draft_team'!$C19,8)="(Keeper)") -> TRUE | I19: =IF(RIGHT(LEFT('2024_Draft_team'!$A19,3))="/",RIGHT(LEFT('2024_Draft_team'!$A19,2),1),RIGHT(LEFT('2024_Draft_team'!$A19,3),2)) -> 18 | J19: =IF(OR(AND(('2024_Draft_team'!$I19-4)<=0,'2024_Draft_team'!$H19=TRUE),('2024_Draft_team'!$R19=TRUE)),"N/A",IF('2024_Draft_team'!$H19=TRUE,'2024_Draft_team'!$I19-4,'2024_Draft_team'!$I19-0)) -> 14 | K19: Harrison | L19: Butker | M19: K | N19: | | O19: KC | P19: (Keeper) | Q19: ='2024_Draft_team'!$K19&'2024_Draft_team'!$L19 -> HarrisonButker | R19: {=IFERROR((INDEX('2024_Transactions'!$J$2:$J$339,MATCH(1,('2024_Draft_team'!$Q19='2024_Transactions'!$C$2:$C$339)*('2024_Draft_team'!$B19='2024_Transactions'!$B$2:$B$339)*('2024_Transactions'!$J$2:$J$339="Dropped"),0))="Dropped"),FALSE)} -> FALSE
A20: 19/1 | B20: Gatordontplay | C20: Khalil Herbert RB | CIN (Keeper) | D20: 0 sec | E20: #89 RB | F20: 39 | G20: 0 | H20: =(RIGHT('2024_Draft_team'!$C20,8)="(Keeper)") -> TRUE | I20: =IF(RIGHT(LEFT('2024_Draft_team'!$A20,3))="/",RIGHT(LEFT('2024_Draft_team'!$A20,2),1),RIGHT(LEFT('2024_Draft_team'!$A20,3),2)) -> 19 | J20: =IF(OR(AND(('2024_Draft_team'!$I20-4)<=0,'2024_Draft_team'!$H20=TRUE),('2024_Draft_team'!$R20=TRUE)),"N/A",IF('2024_Draft_team'!$H20=TRUE,'2024_Draft_team'!$I20-4,'2024_Draft_team'!$I20-0)) -> N/A | K20: Khalil | L20: Herbert | M20: RB | N20: | | O20: CIN | P20: (Keeper) | Q20: ='2024_Draft_team'!$K20&'2024_Draft_team'!$L20 -> KhalilHerbert | R20: {=IFERROR((INDEX('2024_Transactions'!$J$2:$J$339,MATCH(1,('2024_Draft_team'!$Q20='2024_Transactions'!$C$2:$C$339)*('2024_Draft_team'!$B20='2024_Transactions'!$B$2:$B$339)*('2024_Transactions'!$J$2:$J$339="Dropped"),0))="Dropped"),FALSE)} -> TRUE
A21: 20/1 | B21: Gatordontplay | C21: T.J. Hockenson TE | MIN (Keeper) | D21: 0 sec | E21: #31 TE | F21: 173 | G21: 0 | H21: =(RIGHT('2024_Draft_team'!$C21,8)="(Keeper)") -> TRUE | I21: =IF(RIGHT(LEFT('2024_Draft_team'!$A21,3))="/",RIGHT(LEFT('2024_Draft_team'!$A21,2),1),RIGHT(LEFT('2024_Draft_team'!$A21,3),2)) -> 20 | J21: =IF(OR(AND(('2024_Draft_team'!$I21-4)<=0,'2024_Draft_team'!$H21=TRUE),('2024_Draft_team'!$R21=TRUE)),"N/A",IF('2024_Draft_team'!$H21=TRUE,'2024_Draft_team'!$I21-4,'2024_Draft_team'!$I21-0)) -> 16 | K21: T.J. | L21: Hockenson | M21: TE | N21: | | O21: MIN | P21: (Keeper) | Q21: ='2024_Draft_team'!$K21&'2024_Draft_team'!$L21 -> T.J.Hockenson | R21: {=IFERROR((INDEX('2024_Transactions'!$J$2:$J$339,MATCH(1,('2024_Draft_team'!$Q21='2024_Transactions'!$C$2:$C$339)*('2024_Draft_team'!$B21='2024_Transactions'!$B$2:$B$339)*('2024_Transactions'!$J$2:$J$339="Dropped"),0))="Dropped"),FALSE)} -> FALSE
A22: 21/1 | B22: Gatordontplay | C22: Kwity Paye DL | IND (Keeper) | D22: 0 sec | E22: #32 DL | F22: 202 | G22: 47 | H22: =(RIGHT('2024_Draft_team'!$C22,8)="(Keeper)") -> TRUE | I22: =IF(RIGHT(LEFT('2024_Draft_team'!$A22,3))="/",RIGHT(LEFT('2024_Draft_team'!$A22,2),1),RIGHT(LEFT('2024_Draft_team'!$A22,3),2)) -> 21 | J22: =IF(OR(AND(('2024_Draft_team'!$I22-4)<=0,'2024_Draft_team'!$H22=TRUE),('2024_Draft_team'!$R22=TRUE)),"N/A",IF('2024_Draft_team'!$H22=TRUE,'2024_Draft_team'!$I22-4,'2024_Draft_team'!$I22-0)) -> 17 | K22: Kwity | L22: Paye | M22: DL | N22: | | O22: IND | P22: (Keeper) | Q22: ='2024_Draft_team'!$K22&'2024_Draft_team'!$L22 -> KwityPaye | R22: {=IFERROR((INDEX('2024_Transactions'!$J$2:$J$339,MATCH(1,('2024_Draft_team'!$Q22='2024_Transactions'!$C$2:$C$339)*('2024_Draft_team'!$B22='2024_Transactions'!$B$2:$B$339)*('2024_Transactions'!$J$2:$J$339="Dropped"),0))="Dropped"),FALSE)} -> FALSE
A23: 22/1 | B23: Gatordontplay | C23: Joey Bosa DL | LAC (Keeper) | D23: 0 sec | E23: #77 DL | F23: 134 | G23: 71 | H23: =(RIGHT('2024_Draft_team'!$C23,8)="(Keeper)") -> TRUE | I23: =IF(RIGHT(LEFT('2024_Draft_team'!$A23,3))="/",RIGHT(LEFT('2024_Draft_team'!$A23,2),1),RIGHT(LEFT('2024_Draft_team'!$A23,3),2)) -> 22 | J23: =IF(OR(AND(('2024_Draft_team'!$I23-4)<=0,'2024_Draft_team'!$H23=TRUE),('2024_Draft_team'!$R23=TRUE)),"N/A",IF('2024_Draft_team'!$H23=TRUE,'2024_Draft_team'!$I23-4,'2024_Draft_team'!$I23-0)) -> 18 | K23: Joey | L23: Bosa | M23: DL | N23: | | O23: LAC | P23: (Keeper) | Q23: ='2024_Draft_team'!$K23&'2024_Draft_team'!$L23 -> JoeyBosa | R23: {=IFERROR((INDEX('2024_Transactions'!$J$2:$J$339,MATCH(1,('2024_Draft_team'!$Q23='2024_Transactions'!$C$2:$C$339)*('2024_Draft_team'!$B23='2024_Transactions'!$B$2:$B$339)*('2024_Transactions'!$J$2:$J$339="Dropped"),0))="Dropped"),FALSE)} -> FALSE
A24: 23/1 | B24: Gatordontplay | C24: Jamal Adams DB | DET (Keeper) | D24: 0 sec | E24: #328 DB | F24: 15 | G24: 0 | H24: =(RIGHT('2024_Draft_team'!$C24,8)="(Keeper)") -> TRUE | I24: =IF(RIGHT(LEFT('2024_Draft_team'!$A24,3))="/",RIGHT(LEFT('2024_Draft_team'!$A24,2),1),RIGHT(LEFT('2024_Draft_team'!$A24,3),2)) -> 23 | J24: =IF(OR(AND(('2024_Draft_team'!$I24-4)<=0,'2024_Draft_team'!$H24=TRUE),('2024_Draft_team'!$R24=TRUE)),"N/A",IF('2024_Draft_team'!$H24=TRUE,'2024_Draft_team'!$I24-4,'2024_Draft_team'!$I24-0)) -> N/A | K24: Jamal | L24: Adams | M24: DB | N24: | | O24: DET | P24: (Keeper) | Q24: ='2024_Draft_team'!$K24&'2024_Draft_team'!$L24 -> JamalAdams | R24: {=IFERROR((INDEX('2024_Transactions'!$J$2:$J$339,MATCH(1,('2024_Draft_team'!$Q24='2024_Transactions'!$C$2:$C$339)*('2024_Draft_team'!$B24='2024_Transactions'!$B$2:$B$339)*('2024_Transactions'!$J$2:$J$339="Dropped"),0))="Dropped"),FALSE)} -> TRUE
A25: 24/1 | B25: Gatordontplay | C25: Justin Reid DB | KC | D25: 11 hrs 1 min 16 sec | E25: #20 DB | F25: 318 | G25: 267 | H25: =(RIGHT('2024_Draft_team'!$C25,8)="(Keeper)") -> FALSE | I25: =IF(RIGHT(LEFT('2024_Draft_team'!$A25,3))="/",RIGHT(LEFT('2024_Draft_team'!$A25,2),1),RIGHT(LEFT('2024_Draft_team'!$A25,3),2)) -> 24 | J25: =IF(OR(AND(('2024_Draft_team'!$I25-4)<=0,'2024_Draft_team'!$H25=TRUE),('2024_Draft_team'!$R25=TRUE)),"N/A",IF('2024_Draft_team'!$H25=TRUE,'2024_Draft_team'!$I25-4,'2024_Draft_team'!$I25-0)) -> 24 | K25: Justin | L25: Reid | M25: DB | N25: | | O25: KC | Q25: ='2024_Draft_team'!$K25&'2024_Draft_team'!$L25 -> JustinReid | R25: {=IFERROR((INDEX('2024_Transactions'!$J$2:$J$339,MATCH(1,('2024_Draft_team'!$Q25='2024_Transactions'!$C$2:$C$339)*('2024_Draft_team'!$B25='2024_Transactions'!$B$2:$B$339)*('2024_Transactions'!$J$2:$J$339="Dropped"),0))="Dropped"),FALSE)} -> FALSE
A26: 25/1 | B26: Gatordontplay | C26: Courtland Sutton WR | DEN (Keeper) | D26: 0 sec | E26: #10 WR | F26: 415 | G26: 188 | H26: =(RIGHT('2024_Draft_team'!$C26,8)="(Keeper)") -> TRUE | I26: =IF(RIGHT(LEFT('2024_Draft_team'!$A26,3))="/",RIGHT(LEFT('2024_Draft_team'!$A26,2),1),RIGHT(LEFT('2024_Draft_team'!$A26,3),2)) -> 25 | J26: =IF(OR(AND(('2024_Draft_team'!$I26-4)<=0,'2024_Draft_team'!$H26=TRUE),('2024_Draft_team'!$R26=TRUE)),"N/A",IF('2024_Draft_team'!$H26=TRUE,'2024_Draft_team'!$I26-4,'2024_Draft_team'!$I26-0)) -> 21 | K26: Courtland | L26: Sutton | M26: WR | N26: | | O26: DEN | P26: (Keeper) | Q26: ='2024_Draft_team'!$K26&'2024_Draft_team'!$L26 -> CourtlandSutton | R26: {=IFERROR((INDEX('2024_Transactions'!$J$2:$J$339,MATCH(1,('2024_Draft_team'!$Q26='2024_Transactions'!$C$2:$C$339)*('2024_Draft_team'!$B26='2024_Transactions'!$B$2:$B$339)*('2024_Transactions'!$J$2:$J$339="Dropped"),0))="Dropped"),FALSE)} -> FALSE
A27: 26/1 | B27: Gatordontplay | C27: Jalen Thompson DB | ARI | D27: 1 min 3 sec | E27: #65 DB | F27: 236 | G27: 202 | H27: =(RIGHT('2024_Draft_team'!$C27,8)="(Keeper)") -> FALSE | I27: =IF(RIGHT(LEFT('2024_Draft_team'!$A27,3))="/",RIGHT(LEFT('2024_Draft_team'!$A27,2),1),RIGHT(LEFT('2024_Draft_team'!$A27,3),2)) -> 26 | J27: =IF(OR(AND(('2024_Draft_team'!$I27-4)<=0,'2024_Draft_team'!$H27=TRUE),('2024_Draft_team'!$R27=TRUE)),"N/A",IF('2024_Draft_team'!$H27=TRUE,'2024_Draft_team'!$I27-4,'2024_Draft_team'!$I27-0)) -> 26 | K27: Jalen | L27: Thompson | M27: DB | N27: | | O27: ARI | Q27: ='2024_Draft_team'!$K27&'2024_Draft_team'!$L27 -> JalenThompson | R27: {=IFERROR((INDEX('2024_Transactions'!$J$2:$J$339,MATCH(1,('2024_Draft_team'!$Q27='2024_Transactions'!$C$2:$C$339)*('2024_Draft_team'!$B27='2024_Transactions'!$B$2:$B$339)*('2024_Transactions'!$J$2:$J$339="Dropped"),0))="Dropped"),FALSE)} -> FALSE
A28: 27/1 | B28: Gatordontplay | C28: Jake Moody K | SF | D28: 6 min 15 sec (22 hrs 2 min 27 sec) | E28: #26 K | F28: 213 | G28: 22 | H28: =(RIGHT('2024_Draft_team'!$C28,8)="(Keeper)") -> FALSE | I28: =IF(RIGHT(LEFT('2024_Draft_team'!$A28,3))="/",RIGHT(LEFT('2024_Draft_team'!$A28,2),1),RIGHT(LEFT('2024_Draft_team'!$A28,3),2)) -> 27 | J28: =IF(OR(AND(('2024_Draft_team'!$I28-4)<=0,'2024_Draft_team'!$H28=TRUE),('2024_Draft_team'!$R28=TRUE)),"N/A",IF('2024_Draft_team'!$H28=TRUE,'2024_Draft_team'!$I28-4,'2024_Draft_team'!$I28-0)) -> 27 | K28: Jake | L28: Moody | M28: K | N28: | | O28: SF | Q28: ='2024_Draft_team'!$K28&'2024_Draft_team'!$L28 -> JakeMoody | R28: {=IFERROR((INDEX('2024_Transactions'!$J$2:$J$339,MATCH(1,('2024_Draft_team'!$Q28='2024_Transactions'!$C$2:$C$339)*('2024_Draft_team'!$B28='2024_Transactions'!$B$2:$B$339)*('2024_Transactions'!$J$2:$J$339="Dropped"),0))="Dropped"),FALSE)} -> FALSE
A29: 1/2 | B29: Team 4 | C29: Caleb Williams QB | CHI | D29: 17 min 47 sec | E29: #15 QB | F29: 586 | G29: 557 | H29: =(RIGHT('2024_Draft_team'!$C29,8)="(Keeper)") -> FALSE | I29: =IF(RIGHT(LEFT('2024_Draft_team'!$A29,3))="/",RIGHT(LEFT('2024_Draft_team'!$A29,2),1),RIGHT(LEFT('2024_Draft_team'!$A29,3),2)) -> 1 | J29: =IF(OR(AND(('2024_Draft_team'!$I29-4)<=0,'2024_Draft_team'!$H29=TRUE),('2024_Draft_team'!$R29=TRUE)),"N/A",IF('2024_Draft_team'!$H29=TRUE,'2024_Draft_team'!$I29-4,'2024_Draft_team'!$I29-0)) -> 1 | K29: Caleb | L29: Williams | M29: QB | N29: | | O29: CHI | Q29: ='2024_Draft_team'!$K29&'2024_Draft_team'!$L29 -> CalebWilliams | R29: {=IFERROR((INDEX('2024_Transactions'!$J$2:$J$339,MATCH(1,('2024_Draft_team'!$Q29='2024_Transactions'!$C$2:$C$339)*('2024_Draft_team'!$B29='2024_Transactions'!$B$2:$B$339)*('2024_Transactions'!$J$2:$J$339="Dropped"),0))="Dropped"),FALSE)} -> FALSE
A30: 2/2 | B30: Team 4 | C30: Saquon Barkley RB | PHI (Keeper) | D30: 0 sec | E30: #1 RB | F30: 763 | G30: 598 | H30: =(RIGHT('2024_Draft_team'!$C30,8)="(Keeper)") -> TRUE | I30: =IF(RIGHT(LEFT('2024_Draft_team'!$A30,3))="/",RIGHT(LEFT('2024_Draft_team'!$A30,2),1),RIGHT(LEFT('2024_Draft_team'!$A30,3),2)) -> 2 | J30: =IF(OR(AND(('2024_Draft_team'!$I30-4)<=0,'2024_Draft_team'!$H30=TRUE),('2024_Draft_team'!$R30=TRUE)),"N/A",IF('2024_Draft_team'!$H30=TRUE,'2024_Draft_team'!$I30-4,'2024_Draft_team'!$I30-0)) -> N/A | K30: Saquon | L30: Barkley | M30: RB | N30: | | O30: PHI | P30: (Keeper) | Q30: ='2024_Draft_team'!$K30&'2024_Draft_team'!$L30 -> SaquonBarkley | R30: {=IFERROR((INDEX('2024_Transactions'!$J$2:$J$339,MATCH(1,('2024_Draft_team'!$Q30='2024_Transactions'!$C$2:$C$339)*('2024_Draft_team'!$B30='2024_Transactions'!$B$2:$B$339)*('2024_Transactions'!$J$2:$J$339="Dropped"),0))="Dropped"),FALSE)} -> FALSE
A31: 3/2 | B31: Team 4 | C31: Reed Blankenship DB | PHI | D31: 20 sec | E31: #18 DB | F31: 322 | G31: 212 | H31: =(RIGHT('2024_Draft_team'!$C31,8)="(Keeper)") -> FALSE | I31: =IF(RIGHT(LEFT('2024_Draft_team'!$A31,3))="/",RIGHT(LEFT('2024_Draft_team'!$A31,2),1),RIGHT(LEFT('2024_Draft_team'!$A31,3),2)) -> 3 | J31: =IF(OR(AND(('2024_Draft_team'!$I31-4)<=0,'2024_Draft_team'!$H31=TRUE),('2024_Draft_team'!$R31=TRUE)),"N/A",IF('2024_Draft_team'!$H31=TRUE,'2024_Draft_team'!$I31-4,'2024_Draft_team'!$I31-0)) -> 3 | K31: Reed | L31: Blankenship | M31: DB | N31: | | O31: PHI | Q31: ='2024_Draft_team'!$K31&'2024_Draft_team'!$L31 -> ReedBlankenship | R31: {=IFERROR((INDEX('2024_Transactions'!$J$2:$J$339,MATCH(1,('2024_Draft_team'!$Q31='2024_Transactions'!$C$2:$C$339)*('2024_Draft_team'!$B31='2024_Transactions'!$B$2:$B$339)*('2024_Transactions'!$J$2:$J$339="Dropped"),0))="Dropped"),FALSE)} -> FALSE
A32: 4/2 | B32: Team 4 | C32: Tremaine Edmunds LB | CHI | D32: 1 min 25 sec | E32: #46 LB | F32: 278 | G32: 259 | H32: =(RIGHT('2024_Draft_team'!$C32,8)="(Keeper)") -> FALSE | I32: =IF(RIGHT(LEFT('2024_Draft_team'!$A32,3))="/",RIGHT(LEFT('2024_Draft_team'!$A32,2),1),RIGHT(LEFT('2024_Draft_team'!$A32,3),2)) -> 4 | J32: =IF(OR(AND(('2024_Draft_team'!$I32-4)<=0,'2024_Draft_team'!$H32=TRUE),('2024_Draft_team'!$R32=TRUE)),"N/A",IF('2024_Draft_team'!$H32=TRUE,'2024_Draft_team'!$I32-4,'2024_Draft_team'!$I32-0)) -> 4 | K32: Tremaine | L32: Edmunds | M32: LB | N32: | | O32: CHI | Q32: ='2024_Draft_team'!$K32&'2024_Draft_team'!$L32 -> TremaineEdmunds | R32: {=IFERROR((INDEX('2024_Transactions'!$J$2:$J$339,MATCH(1,('2024_Draft_team'!$Q32='2024_Transactions'!$C$2:$C$339)*('2024_Draft_team'!$B32='2024_Transactions'!$B$2:$B$339)*('2024_Transactions'!$J$2:$J$339="Dropped"),0))="Dropped"),FALSE)} -> FALSE
